Script started on 2022-02-16 09:43:31-03:00 [TERM="xterm-256color" TTY="/dev/pts/6" COLUMNS="102" LINES="21"]
Traceback (most recent call last):
  File "/usr/lib/python3.8/runpy.py", line 194, in _run_module_as_main
    return _run_code(code, main_globals, None,
  File "/usr/lib/python3.8/runpy.py", line 87, in _run_code
    exec(code, run_globals)
  File "/home/bruno/.vscode/extensions/ms-python.python-2022.0.1786462952/pythonFiles/lib/python/debugpy/launcher/__main__.py", line 97, in <module>
    main()
  File "/home/bruno/.vscode/extensions/ms-python.python-2022.0.1786462952/pythonFiles/lib/python/debugpy/launcher/__main__.py", line 53, in main
    launcher.connect(host, port)
  File "/home/bruno/.vscode/extensions/ms-python.python-2022.0.1786462952/pythonFiles/lib/python/debugpy/launcher/../../debugpy/launcher/__init__.py", line 34, in connect
    sock.connect((host, port))
ConnectionRefusedError: [Errno 111] Connection refused

Script done on 2022-02-16 09:43:32-03:00 [COMMAND_EXIT_CODE="1"]
